Traceback (most recent call last):
  File "C:\Users\mirjam\anaconda3\lib\site-packages\jupyter_cache\executors\utils.py", line 51, in single_nb_execution
    executenb(
  File "C:\Users\mirjam\anaconda3\lib\site-packages\nbclient\client.py", line 1204, in execute
    return NotebookClient(nb=nb, resources=resources, km=km, **kwargs).execute()
  File "C:\Users\mirjam\anaconda3\lib\site-packages\nbclient\util.py", line 84, in wrapped
    return just_run(coro(*args, **kwargs))
  File "C:\Users\mirjam\anaconda3\lib\site-packages\nbclient\util.py", line 62, in just_run
    return loop.run_until_complete(coro)
  File "C:\Users\mirjam\anaconda3\lib\asyncio\base_events.py", line 647, in run_until_complete
    return future.result()
  File "C:\Users\mirjam\anaconda3\lib\site-packages\nbclient\client.py", line 663, in async_execute
    await self.async_execute_cell(
  File "C:\Users\mirjam\anaconda3\lib\site-packages\nbclient\client.py", line 965, in async_execute_cell
    await self._check_raise_for_error(cell, cell_index, exec_reply)
  File "C:\Users\mirjam\anaconda3\lib\site-packages\nbclient\client.py", line 862, in _check_raise_for_error
    raise CellExecutionError.from_cell_and_msg(cell, exec_reply_content)
nbclient.exceptions.CellExecutionError: An error occurred while executing the following cell:
------------------
page = 'p001'

for item in root_didl.find_all('Component'):
    identifier_page = item.get('dc:identifier')
    if page in identifier_page:
        for article in item.find_all('dcx'):
                a_type = article.find('subject')
                if a_type is not None:
                    title = article.find('title')
                    identifier = article.find('identifier')
                    article_list.append([page, a_type.text, title.text, identifier.text])
 
import pandas as pd
articles = pd.DataFrame(article_list, columns = ['Page', 'Type', 'Title', 'Identifier'])

articles
------------------

[1;31m---------------------------------------------------------------------------[0m
[1;31mNameError[0m                                 Traceback (most recent call last)
Input [1;32mIn [11][0m, in [0;36m<cell line: 3>[1;34m()[0m
[0;32m      9[0m                     title [38;5;241m=[39m article[38;5;241m.[39mfind([38;5;124m'[39m[38;5;124mtitle[39m[38;5;124m'[39m)
[0;32m     10[0m                     identifier [38;5;241m=[39m article[38;5;241m.[39mfind([38;5;124m'[39m[38;5;124midentifier[39m[38;5;124m'[39m)
[1;32m---> 11[0m                     [43marticle_list[49m[38;5;241m.[39mappend([page, a_type[38;5;241m.[39mtext, title[38;5;241m.[39mtext, identifier[38;5;241m.[39mtext])
[0;32m     13[0m [38;5;28;01mimport[39;00m [38;5;21;01mpandas[39;00m [38;5;28;01mas[39;00m [38;5;21;01mpd[39;00m
[0;32m     14[0m articles [38;5;241m=[39m pd[38;5;241m.[39mDataFrame(article_list, columns [38;5;241m=[39m [[38;5;124m'[39m[38;5;124mPage[39m[38;5;124m'[39m, [38;5;124m'[39m[38;5;124mType[39m[38;5;124m'[39m, [38;5;124m'[39m[38;5;124mTitle[39m[38;5;124m'[39m, [38;5;124m'[39m[38;5;124mIdentifier[39m[38;5;124m'[39m])

[1;31mNameError[0m: name 'article_list' is not defined
NameError: name 'article_list' is not defined

